<?xml version="1.0" ?>
<!-- =================================================================================== -->
<!-- |    This document was autogenerated by xacro from ./dog.xacro                    | -->
<!-- |    EDITING THIS FILE BY HAND IS NOT RECOMMENDED                                 | -->
<!-- =================================================================================== -->
<robot name="dog">
  <!-- 躯干绕z轴转动惯量(kg·m²) -->
  <!-- 髋关节绕z轴转动惯量(kg·m²) -->
  <!-- 大腿绕z轴转动惯量(kg·m²) -->
  <!-- 小腿绕z轴转动惯量(kg·m²) -->
  <!-- 脚部绕z轴转动惯量(kg·m²) -->
  <!-- 脚部z轴方向偏移量(m) -->
  <!-- 髋x轴关节最大力矩(N·m) -->
  <!-- 髋y轴关节最大力矩(N·m) -->
  <!-- 膝关节最大力矩(N·m) -->
  <link name="TORSO">
    <inertial>
      <origin xyz="0 0 0"/>
      <mass value="5.6056"/>
      <inertia ixx="0.02456" ixy="0" ixz="0" iyy="0.05518" iyz="0" izz="0.07016"/>
    </inertial>
    <visual>
      <geometry>
        <mesh filename="package://dog_bringup/meshes/torso.STL"/>
      </geometry>
    </visual>
    <collision>
      <origin xyz="0 0 0.01"/>
      <geometry>
        <box size="0.5 0.1 0.12"/>
      </geometry>
    </collision>
    <collision>
      <origin xyz="0 0 0.01"/>
      <geometry>
        <box size="0.25 0.2 0.12"/>
      </geometry>
    </collision>
  </link>
  <link name="imu_link">
    <inertial>
      <mass value="0.001"/>
      <origin rpy="0 0 0" xyz="0 0 0"/>
      <inertia ixx="1e-09" ixy="0.0" ixz="0.0" iyy="1e-09" iyz="0.0" izz="1e-09"/>
    </inertial>
  </link>
  <joint name="imu_joint" type="fixed">
    <parent link="TORSO"/>
    <child link="imu_link"/>
    <origin rpy="0 0 0" xyz="0 0 0"/>
  </joint>
  <link name="base_link"/>
  <joint name="base_joint" type="fixed">
    <parent link="base_link"/>
    <child link="TORSO"/>
    <origin rpy="0 0 0" xyz="0 0 0"/>
  </joint>
  <link name="FL_HIP">
    <inertial>
      <origin xyz="-0.00601 -0.0066532 0.00034295"/>
      <mass value="0.55"/>
      <inertia ixx="0.0003949" ixy="0" ixz="0" iyy="0.0004028" iyz="0" izz="0.0004472"/>
    </inertial>
    <visual>
      <geometry>
        <mesh filename="package://dog_bringup/meshes/hip.STL" scale="1 1 1"/>
      </geometry>
    </visual>
    <collision>
      <origin rpy="1.57079632 0 0" xyz="0 0.05 0"/>
      <geometry>
        <cylinder length="0.15" radius="0.04"/>
      </geometry>
    </collision>
  </link>
  <joint name="FL_HipX_joint" type="revolute">
    <origin xyz="0.1745 0.062 0"/>
    <parent link="TORSO"/>
    <child link="FL_HIP"/>
    <axis xyz="-1 0 0"/>
    <limit effort="24" lower="-0.523" upper="0.523" velocity="26.2"/>
    <dynamics damping="0.05" friction="0.01"/>
  </joint>
  <link name="FL_THIGH">
    <inertial>
      <origin xyz="-0.0039245 -0.014632 -0.025146"/>
      <mass value="0.86"/>
      <inertia ixx="0.005736" ixy="0" ixz="0" iyy="0.00496" iyz="0" izz="0.001436"/>
    </inertial>
    <visual>
      <geometry>
        <mesh filename="package://dog_bringup/meshes/thigh.STL" scale="1 1 1"/>
      </geometry>
    </visual>
    <collision>
      <origin xyz="-0.015 0 -0.08"/>
      <geometry>
        <box size="0.04 0.045 0.2"/>
      </geometry>
    </collision>
  </link>
  <joint name="FL_HipY_joint" type="revolute">
    <origin xyz="0 0.09735 0"/>
    <parent link="FL_HIP"/>
    <child link="FL_THIGH"/>
    <axis xyz="0 -1 0"/>
    <limit effort="24" lower="-2.67" upper="0.314" velocity="26.2"/>
    <dynamics damping="0.05" friction="0.01"/>
  </joint>
  <link name="FL_SHANK">
    <inertial>
      <origin xyz="0.0064794 -1.45e-06 -0.12157"/>
      <mass value="0.153"/>
      <inertia ixx="0.00089039" ixy="0" ixz="0" iyy="0.00090672" iyz="0" izz="3.1266e-05"/>
    </inertial>
    <visual>
      <geometry>
        <mesh filename="package://dog_bringup/meshes/shank.STL"/>
      </geometry>
    </visual>
    <collision>
      <origin rpy="0 -0.2 0" xyz="0.005 0 -0.03"/>
      <geometry>
        <cylinder length="0.12" radius="0.015"/>
      </geometry>
    </collision>
    <collision>
      <origin rpy="0 0.15 0" xyz="0.01 0 -0.14"/>
      <geometry>
        <cylinder length="0.10" radius="0.015"/>
      </geometry>
    </collision>
  </link>
  <joint name="FL_Knee_joint" type="revolute">
    <origin xyz="0 0 -0.2"/>
    <parent link="FL_THIGH"/>
    <child link="FL_SHANK"/>
    <axis xyz="0 -1 0"/>
    <limit effort="36" lower="0.524" upper="2.792" velocity="17.3"/>
    <dynamics damping="0.05" friction="0.01"/>
  </joint>
  <link name="FL_FOOT">
    <collision>
      <origin rpy="1.57079632679 0 0"/>
      <geometry>
        <sphere radius="0.023"/>
      </geometry>
    </collision>
    <inertial>
      <mass value="0.02"/>
      <inertia ixx="0.0001" ixy="0" ixz="0" iyy="0.0001" iyz="0" izz="0.0001"/>
    </inertial>
  </link>
  <joint dont_collapse="true" name="FL_Ankle" type="fixed">
    <parent link="FL_SHANK"/>
    <child link="FL_FOOT"/>
    <origin xyz="0 0 -0.21012"/>
  </joint>
  <gazebo reference="FL_Ankle">
    <preserveFixedJoint>true</preserveFixedJoint>
  </gazebo>
  <gazebo reference="FL_FOOT">
    <mu1>1.5</mu1>
    <mu2>1.5</mu2>
    <kp>1000000.0</kp>
    <kd>100.0</kd>
    <maxVel>0.0</maxVel>
    <minDepth>0.001</minDepth>
    <sensor name="FL_contact_sensor" type="contact">
      <always_on>true</always_on>
      <update_rate>1000</update_rate>
      <contact>
        <collision>FL_FOOT_collision</collision>
      </contact>
    </sensor>
  </gazebo>
  <link name="FR_HIP">
    <inertial>
      <origin xyz="-0.00601 0.0066532 0.00034295"/>
      <mass value="0.55"/>
      <inertia ixx="0.0003949" ixy="0" ixz="0" iyy="0.0004028" iyz="0" izz="0.0004472"/>
    </inertial>
    <visual>
      <geometry>
        <mesh filename="package://dog_bringup/meshes/hip.STL" scale="1 -1 1"/>
      </geometry>
    </visual>
    <collision>
      <origin rpy="1.57079632 0 0" xyz="0 -0.05 0"/>
      <geometry>
        <cylinder length="0.15" radius="0.04"/>
      </geometry>
    </collision>
  </link>
  <joint name="FR_HipX_joint" type="revolute">
    <origin xyz="0.1745 -0.062 0"/>
    <parent link="TORSO"/>
    <child link="FR_HIP"/>
    <axis xyz="-1 0 0"/>
    <limit effort="24" lower="-0.523" upper="0.523" velocity="26.2"/>
    <dynamics damping="0.05" friction="0.01"/>
  </joint>
  <link name="FR_THIGH">
    <inertial>
      <origin xyz="-0.0039245 0.014632 -0.025146"/>
      <mass value="0.86"/>
      <inertia ixx="0.005736" ixy="0" ixz="0" iyy="0.00496" iyz="0" izz="0.001436"/>
    </inertial>
    <visual>
      <geometry>
        <mesh filename="package://dog_bringup/meshes/thigh.STL" scale="1 -1 1"/>
      </geometry>
    </visual>
    <collision>
      <origin xyz="-0.015 0 -0.08"/>
      <geometry>
        <box size="0.04 0.045 0.2"/>
      </geometry>
    </collision>
  </link>
  <joint name="FR_HipY_joint" type="revolute">
    <origin xyz="0 -0.09735 0"/>
    <parent link="FR_HIP"/>
    <child link="FR_THIGH"/>
    <axis xyz="0 -1 0"/>
    <limit effort="24" lower="-2.67" upper="0.314" velocity="26.2"/>
    <dynamics damping="0.05" friction="0.01"/>
  </joint>
  <link name="FR_SHANK">
    <inertial>
      <origin xyz="0.0064794 -1.45e-06 -0.12157"/>
      <mass value="0.153"/>
      <inertia ixx="0.00089039" ixy="0" ixz="0" iyy="0.00090672" iyz="0" izz="3.1266e-05"/>
    </inertial>
    <visual>
      <geometry>
        <mesh filename="package://dog_bringup/meshes/shank.STL"/>
      </geometry>
    </visual>
    <collision>
      <origin rpy="0 -0.2 0" xyz="0.005 0 -0.03"/>
      <geometry>
        <cylinder length="0.12" radius="0.015"/>
      </geometry>
    </collision>
    <collision>
      <origin rpy="0 0.15 0" xyz="0.01 0 -0.14"/>
      <geometry>
        <cylinder length="0.10" radius="0.015"/>
      </geometry>
    </collision>
  </link>
  <joint name="FR_Knee_joint" type="revolute">
    <origin xyz="0 0 -0.2"/>
    <parent link="FR_THIGH"/>
    <child link="FR_SHANK"/>
    <axis xyz="0 -1 0"/>
    <limit effort="36" lower="0.524" upper="2.792" velocity="17.3"/>
    <dynamics damping="0.05" friction="0.01"/>
  </joint>
  <link name="FR_FOOT">
    <collision>
      <origin rpy="1.57079632679 0 0"/>
      <geometry>
        <sphere radius="0.023"/>
      </geometry>
    </collision>
    <inertial>
      <mass value="0.02"/>
      <inertia ixx="0.0001" ixy="0" ixz="0" iyy="0.0001" iyz="0" izz="0.0001"/>
    </inertial>
  </link>
  <joint dont_collapse="true" name="FR_Ankle" type="fixed">
    <parent link="FR_SHANK"/>
    <child link="FR_FOOT"/>
    <origin xyz="0 0 -0.21012"/>
  </joint>
  <gazebo reference="FR_Ankle">
    <preserveFixedJoint>true</preserveFixedJoint>
  </gazebo>
  <gazebo reference="FR_FOOT">
    <mu1>1.5</mu1>
    <mu2>1.5</mu2>
    <kp>1000000.0</kp>
    <kd>100.0</kd>
    <maxVel>0.0</maxVel>
    <minDepth>0.001</minDepth>
    <sensor name="FR_contact_sensor" type="contact">
      <always_on>true</always_on>
      <update_rate>1000</update_rate>
      <contact>
        <collision>FR_FOOT_collision</collision>
      </contact>
    </sensor>
  </gazebo>
  <link name="HL_HIP">
    <inertial>
      <origin xyz="-0.00601 -0.0066532 0.00034295"/>
      <mass value="0.55"/>
      <inertia ixx="0.0003949" ixy="0" ixz="0" iyy="0.0004028" iyz="0" izz="0.0004472"/>
    </inertial>
    <visual>
      <geometry>
        <mesh filename="package://dog_bringup/meshes/hip.STL" scale="-1 1 1"/>
      </geometry>
    </visual>
    <collision>
      <origin rpy="1.57079632 0 0" xyz="0 0.05 0"/>
      <geometry>
        <cylinder length="0.15" radius="0.04"/>
      </geometry>
    </collision>
  </link>
  <joint name="HL_HipX_joint" type="revolute">
    <origin xyz="-0.1745 0.062 0"/>
    <parent link="TORSO"/>
    <child link="HL_HIP"/>
    <axis xyz="-1 0 0"/>
    <limit effort="24" lower="-0.523" upper="0.523" velocity="26.2"/>
    <dynamics damping="0.05" friction="0.01"/>
  </joint>
  <link name="HL_THIGH">
    <inertial>
      <origin xyz="-0.0039245 -0.014632 -0.025146"/>
      <mass value="0.86"/>
      <inertia ixx="0.005736" ixy="0" ixz="0" iyy="0.00496" iyz="0" izz="0.001436"/>
    </inertial>
    <visual>
      <geometry>
        <mesh filename="package://dog_bringup/meshes/thigh.STL" scale="1 1 1"/>
      </geometry>
    </visual>
    <collision>
      <origin xyz="-0.015 0 -0.08"/>
      <geometry>
        <box size="0.04 0.045 0.2"/>
      </geometry>
    </collision>
  </link>
  <joint name="HL_HipY_joint" type="revolute">
    <origin xyz="0 0.09735 0"/>
    <parent link="HL_HIP"/>
    <child link="HL_THIGH"/>
    <axis xyz="0 -1 0"/>
    <limit effort="24" lower="-2.67" upper="0.314" velocity="26.2"/>
    <dynamics damping="0.05" friction="0.01"/>
  </joint>
  <link name="HL_SHANK">
    <inertial>
      <origin xyz="0.0064794 -1.45e-06 -0.12157"/>
      <mass value="0.153"/>
      <inertia ixx="0.00089039" ixy="0" ixz="0" iyy="0.00090672" iyz="0" izz="3.1266e-05"/>
    </inertial>
    <visual>
      <geometry>
        <mesh filename="package://dog_bringup/meshes/shank.STL"/>
      </geometry>
    </visual>
    <collision>
      <origin rpy="0 -0.2 0" xyz="0.005 0 -0.03"/>
      <geometry>
        <cylinder length="0.12" radius="0.015"/>
      </geometry>
    </collision>
    <collision>
      <origin rpy="0 0.15 0" xyz="0.01 0 -0.14"/>
      <geometry>
        <cylinder length="0.10" radius="0.015"/>
      </geometry>
    </collision>
  </link>
  <joint name="HL_Knee_joint" type="revolute">
    <origin xyz="0 0 -0.2"/>
    <parent link="HL_THIGH"/>
    <child link="HL_SHANK"/>
    <axis xyz="0 -1 0"/>
    <limit effort="36" lower="0.524" upper="2.792" velocity="17.3"/>
    <dynamics damping="0.05" friction="0.01"/>
  </joint>
  <link name="HL_FOOT">
    <collision>
      <origin rpy="1.57079632679 0 0"/>
      <geometry>
        <sphere radius="0.023"/>
      </geometry>
    </collision>
    <inertial>
      <mass value="0.02"/>
      <inertia ixx="0.0001" ixy="0" ixz="0" iyy="0.0001" iyz="0" izz="0.0001"/>
    </inertial>
  </link>
  <joint dont_collapse="true" name="HL_Ankle" type="fixed">
    <parent link="HL_SHANK"/>
    <child link="HL_FOOT"/>
    <origin xyz="0 0 -0.21012"/>
  </joint>
  <gazebo reference="HL_Ankle">
    <preserveFixedJoint>true</preserveFixedJoint>
  </gazebo>
  <gazebo reference="HL_FOOT">
    <mu1>1.5</mu1>
    <mu2>1.5</mu2>
    <kp>1000000.0</kp>
    <kd>100.0</kd>
    <maxVel>0.0</maxVel>
    <minDepth>0.001</minDepth>
    <sensor name="HL_contact_sensor" type="contact">
      <always_on>true</always_on>
      <update_rate>1000</update_rate>
      <contact>
        <collision>HL_FOOT_collision</collision>
      </contact>
    </sensor>
  </gazebo>
  <link name="HR_HIP">
    <inertial>
      <origin xyz="-0.00601 0.0066532 0.00034295"/>
      <mass value="0.55"/>
      <inertia ixx="0.0003949" ixy="0" ixz="0" iyy="0.0004028" iyz="0" izz="0.0004472"/>
    </inertial>
    <visual>
      <geometry>
        <mesh filename="package://dog_bringup/meshes/hip.STL" scale="-1 -1 1"/>
      </geometry>
    </visual>
    <collision>
      <origin rpy="1.57079632 0 0" xyz="0 -0.05 0"/>
      <geometry>
        <cylinder length="0.15" radius="0.04"/>
      </geometry>
    </collision>
  </link>
  <joint name="HR_HipX_joint" type="revolute">
    <origin xyz="-0.1745 -0.062 0"/>
    <parent link="TORSO"/>
    <child link="HR_HIP"/>
    <axis xyz="-1 0 0"/>
    <limit effort="24" lower="-0.523" upper="0.523" velocity="26.2"/>
    <dynamics damping="0.05" friction="0.01"/>
  </joint>
  <link name="HR_THIGH">
    <inertial>
      <origin xyz="-0.0039245 0.014632 -0.025146"/>
      <mass value="0.86"/>
      <inertia ixx="0.005736" ixy="0" ixz="0" iyy="0.00496" iyz="0" izz="0.001436"/>
    </inertial>
    <visual>
      <geometry>
        <mesh filename="package://dog_bringup/meshes/thigh.STL" scale="1 -1 1"/>
      </geometry>
    </visual>
    <collision>
      <origin xyz="-0.015 0 -0.08"/>
      <geometry>
        <box size="0.04 0.045 0.2"/>
      </geometry>
    </collision>
  </link>
  <joint name="HR_HipY_joint" type="revolute">
    <origin xyz="0 -0.09735 0"/>
    <parent link="HR_HIP"/>
    <child link="HR_THIGH"/>
    <axis xyz="0 -1 0"/>
    <limit effort="24" lower="-2.67" upper="0.314" velocity="26.2"/>
    <dynamics damping="0.05" friction="0.01"/>
  </joint>
  <link name="HR_SHANK">
    <inertial>
      <origin xyz="0.0064794 -1.45e-06 -0.12157"/>
      <mass value="0.153"/>
      <inertia ixx="0.00089039" ixy="0" ixz="0" iyy="0.00090672" iyz="0" izz="3.1266e-05"/>
    </inertial>
    <visual>
      <geometry>
        <mesh filename="package://dog_bringup/meshes/shank.STL"/>
      </geometry>
    </visual>
    <collision>
      <origin rpy="0 -0.2 0" xyz="0.005 0 -0.03"/>
      <geometry>
        <cylinder length="0.12" radius="0.015"/>
      </geometry>
    </collision>
    <collision>
      <origin rpy="0 0.15 0" xyz="0.01 0 -0.14"/>
      <geometry>
        <cylinder length="0.10" radius="0.015"/>
      </geometry>
    </collision>
  </link>
  <joint name="HR_Knee_joint" type="revolute">
    <origin xyz="0 0 -0.2"/>
    <parent link="HR_THIGH"/>
    <child link="HR_SHANK"/>
    <axis xyz="0 -1 0"/>
    <limit effort="36" lower="0.524" upper="2.792" velocity="17.3"/>
    <dynamics damping="0.05" friction="0.01"/>
  </joint>
  <link name="HR_FOOT">
    <collision>
      <origin rpy="1.57079632679 0 0"/>
      <geometry>
        <sphere radius="0.023"/>
      </geometry>
    </collision>
    <inertial>
      <mass value="0.02"/>
      <inertia ixx="0.0001" ixy="0" ixz="0" iyy="0.0001" iyz="0" izz="0.0001"/>
    </inertial>
  </link>
  <joint dont_collapse="true" name="HR_Ankle" type="fixed">
    <parent link="HR_SHANK"/>
    <child link="HR_FOOT"/>
    <origin xyz="0 0 -0.21012"/>
  </joint>
  <gazebo reference="HR_Ankle">
    <preserveFixedJoint>true</preserveFixedJoint>
  </gazebo>
  <gazebo reference="HR_FOOT">
    <mu1>1.5</mu1>
    <mu2>1.5</mu2>
    <kp>1000000.0</kp>
    <kd>100.0</kd>
    <maxVel>0.0</maxVel>
    <minDepth>0.001</minDepth>
    <sensor name="HR_contact_sensor" type="contact">
      <always_on>true</always_on>
      <update_rate>1000</update_rate>
      <contact>
        <collision>HR_FOOT_collision</collision>
      </contact>
    </sensor>
  </gazebo>
  <ros2_control name="dog_System" type="system">
    <hardware>
      <!-- <plugin>gazebo_ros2_control/GazeboSystem</plugin> -->
      <plugin>dog_hardware/DogGazeboHW</plugin>
      <param name="delay">0.009</param>
      <param name="imu_accel_var">0.01</param>
      <param name="imu_gyro_var">0.0004</param>
      <param name="imu_ori_var">0.0012</param>
    </hardware>
    <sensor name="imu_sensor">
      <state_interface name="orientation.x"/>
      <state_interface name="orientation.y"/>
      <state_interface name="orientation.z"/>
      <state_interface name="orientation.w"/>
      <state_interface name="angular_velocity.x"/>
      <state_interface name="angular_velocity.y"/>
      <state_interface name="angular_velocity.z"/>
      <state_interface name="linear_acceleration.x"/>
      <state_interface name="linear_acceleration.y"/>
      <state_interface name="linear_acceleration.z"/>
      <state_interface name="orientation_covariance"/>
      <state_interface name="angular_velocity_covariance"/>
      <state_interface name="linear_acceleration_covariance"/>
    </sensor>
    <sensor name="FL_contact_sensor">
      <state_interface name="contact"/>
    </sensor>
    <sensor name="FR_contact_sensor">
      <state_interface name="contact"/>
    </sensor>
    <sensor name="HL_contact_sensor">
      <state_interface name="contact"/>
    </sensor>
    <sensor name="HR_contact_sensor">
      <state_interface name="contact"/>
    </sensor>
    <joint name="FL_HipX_joint">
      <command_interface name="effort">
        <param name="min">-24</param>
        <param name="max">24</param>
      </command_interface>
      <command_interface name="position"/>
      <command_interface name="velocity"/>
      <command_interface name="kp"/>
      <command_interface name="kd"/>
      <command_interface name="mode"/>
      <state_interface name="driver_tem"/>
      <state_interface name="motor_tem"/>
      <state_interface name="error_code"/>
      <state_interface name="position"/>
      <state_interface name="velocity"/>
      <state_interface name="effort"/>
    </joint>
    <joint name="FL_HipY_joint">
      <command_interface name="effort">
        <param name="min">-24</param>
        <param name="max">24</param>
      </command_interface>
      <command_interface name="position"/>
      <command_interface name="velocity"/>
      <command_interface name="kp"/>
      <command_interface name="kd"/>
      <command_interface name="mode"/>
      <state_interface name="driver_tem"/>
      <state_interface name="motor_tem"/>
      <state_interface name="error_code"/>
      <state_interface name="position"/>
      <state_interface name="velocity"/>
      <state_interface name="effort"/>
    </joint>
    <joint name="FL_Knee_joint">
      <command_interface name="effort">
        <param name="min">-36</param>
        <param name="max">36</param>
      </command_interface>
      <command_interface name="position"/>
      <command_interface name="velocity"/>
      <command_interface name="kp"/>
      <command_interface name="kd"/>
      <command_interface name="mode"/>
      <state_interface name="driver_tem"/>
      <state_interface name="motor_tem"/>
      <state_interface name="error_code"/>
      <state_interface name="position"/>
      <state_interface name="velocity"/>
      <state_interface name="effort"/>
    </joint>
    <joint name="FR_HipX_joint">
      <command_interface name="effort">
        <param name="min">-24</param>
        <param name="max">24</param>
      </command_interface>
      <command_interface name="position"/>
      <command_interface name="velocity"/>
      <command_interface name="kp"/>
      <command_interface name="kd"/>
      <command_interface name="mode"/>
      <state_interface name="driver_tem"/>
      <state_interface name="motor_tem"/>
      <state_interface name="error_code"/>
      <state_interface name="position"/>
      <state_interface name="velocity"/>
      <state_interface name="effort"/>
    </joint>
    <joint name="FR_HipY_joint">
      <command_interface name="effort">
        <param name="min">-24</param>
        <param name="max">24</param>
      </command_interface>
      <command_interface name="position"/>
      <command_interface name="velocity"/>
      <command_interface name="kp"/>
      <command_interface name="kd"/>
      <command_interface name="mode"/>
      <state_interface name="driver_tem"/>
      <state_interface name="motor_tem"/>
      <state_interface name="error_code"/>
      <state_interface name="position"/>
      <state_interface name="velocity"/>
      <state_interface name="effort"/>
    </joint>
    <joint name="FR_Knee_joint">
      <command_interface name="effort">
        <param name="min">-36</param>
        <param name="max">36</param>
      </command_interface>
      <command_interface name="position"/>
      <command_interface name="velocity"/>
      <command_interface name="kp"/>
      <command_interface name="kd"/>
      <command_interface name="mode"/>
      <state_interface name="driver_tem"/>
      <state_interface name="motor_tem"/>
      <state_interface name="error_code"/>
      <state_interface name="position"/>
      <state_interface name="velocity"/>
      <state_interface name="effort"/>
    </joint>
    <joint name="HL_HipX_joint">
      <command_interface name="effort">
        <param name="min">-24</param>
        <param name="max">24</param>
      </command_interface>
      <command_interface name="position"/>
      <command_interface name="velocity"/>
      <command_interface name="kp"/>
      <command_interface name="kd"/>
      <command_interface name="mode"/>
      <state_interface name="driver_tem"/>
      <state_interface name="motor_tem"/>
      <state_interface name="error_code"/>
      <state_interface name="position"/>
      <state_interface name="velocity"/>
      <state_interface name="effort"/>
    </joint>
    <joint name="HL_HipY_joint">
      <command_interface name="effort">
        <param name="min">-24</param>
        <param name="max">24</param>
      </command_interface>
      <command_interface name="position"/>
      <command_interface name="velocity"/>
      <command_interface name="kp"/>
      <command_interface name="kd"/>
      <command_interface name="mode"/>
      <state_interface name="driver_tem"/>
      <state_interface name="motor_tem"/>
      <state_interface name="error_code"/>
      <state_interface name="position"/>
      <state_interface name="velocity"/>
      <state_interface name="effort"/>
    </joint>
    <joint name="HL_Knee_joint">
      <command_interface name="effort">
        <param name="min">-36</param>
        <param name="max">36</param>
      </command_interface>
      <command_interface name="position"/>
      <command_interface name="velocity"/>
      <command_interface name="kp"/>
      <command_interface name="kd"/>
      <command_interface name="mode"/>
      <state_interface name="driver_tem"/>
      <state_interface name="motor_tem"/>
      <state_interface name="error_code"/>
      <state_interface name="position"/>
      <state_interface name="velocity"/>
      <state_interface name="effort"/>
    </joint>
    <joint name="HR_HipX_joint">
      <command_interface name="effort">
        <param name="min">-24</param>
        <param name="max">24</param>
      </command_interface>
      <command_interface name="position"/>
      <command_interface name="velocity"/>
      <command_interface name="kp"/>
      <command_interface name="kd"/>
      <command_interface name="mode"/>
      <state_interface name="driver_tem"/>
      <state_interface name="motor_tem"/>
      <state_interface name="error_code"/>
      <state_interface name="position"/>
      <state_interface name="velocity"/>
      <state_interface name="effort"/>
    </joint>
    <joint name="HR_HipY_joint">
      <command_interface name="effort">
        <param name="min">-24</param>
        <param name="max">24</param>
      </command_interface>
      <command_interface name="position"/>
      <command_interface name="velocity"/>
      <command_interface name="kp"/>
      <command_interface name="kd"/>
      <command_interface name="mode"/>
      <state_interface name="driver_tem"/>
      <state_interface name="motor_tem"/>
      <state_interface name="error_code"/>
      <state_interface name="position"/>
      <state_interface name="velocity"/>
      <state_interface name="effort"/>
    </joint>
    <joint name="HR_Knee_joint">
      <command_interface name="effort">
        <param name="min">-36</param>
        <param name="max">36</param>
      </command_interface>
      <command_interface name="position"/>
      <command_interface name="velocity"/>
      <command_interface name="kp"/>
      <command_interface name="kd"/>
      <command_interface name="mode"/>
      <state_interface name="driver_tem"/>
      <state_interface name="motor_tem"/>
      <state_interface name="error_code"/>
      <state_interface name="position"/>
      <state_interface name="velocity"/>
      <state_interface name="effort"/>
    </joint>
  </ros2_control>
  <gazebo reference="imu_link">
    <sensor name="imu_sensor" type="imu">
      <always_on>true</always_on>
      <update_rate>1000</update_rate>
      <imu>
        <orientation>
          <x>
            <noise type="gaussian">
              <stddev>0.034641016151377546</stddev>
            </noise>
          </x>
          <y>
            <noise type="gaussian">
              <stddev>0.034641016151377546</stddev>
            </noise>
          </y>
          <z>
            <noise type="gaussian">
              <stddev>0.034641016151377546</stddev>
            </noise>
          </z>
        </orientation>
        <linear_acceleration>
          <x>
            <noise type="gaussian">
              <stddev>0.1</stddev>
              <bias_mean>0.0</bias_mean>
            </noise>
          </x>
          <y>
            <noise type="gaussian">
              <stddev>0.1</stddev>
              <bias_mean>0.0</bias_mean>
            </noise>
          </y>
          <z>
            <noise type="gaussian">
              <stddev>0.1</stddev>
              <bias_mean>0.0</bias_mean>
            </noise>
          </z>
        </linear_acceleration>
        <angular_velocity>
          <x>
            <noise type="gaussian">
              <stddev>0.02</stddev>
              <bias_mean>0.0</bias_mean>
            </noise>
          </x>
          <y>
            <noise type="gaussian">
              <stddev>0.02</stddev>
              <bias_mean>0.0</bias_mean>
            </noise>
          </y>
          <z>
            <noise type="gaussian">
              <stddev>0.02</stddev>
              <bias_mean>0.0</bias_mean>
            </noise>
          </z>
        </angular_velocity>
      </imu>
    </sensor>
  </gazebo>
  <gazebo>
    <plugin filename="libgazebo_ros2_control.so" name="gazebo_ros2_control">
      <parameters>/home/cys/Project_Date/ROS2_workspace/dog_ws/install/dog_bringup/share/dog_bringup/config/robot_controllers.yaml</parameters>
      <robot_param>robot_description</robot_param>
      <robot_param_node>robot_state_publisher</robot_param_node>
    </plugin>
  </gazebo>
</robot>
